{
 "cells": [
  {
   "cell_type": "code",
   "execution_count": 1,
   "id": "61850dc9",
   "metadata": {},
   "outputs": [],
   "source": [
    "import numpy as np\n",
    "import pandas as pd\n",
    "import zipfile\n",
    "\n",
    "import keras\n",
    "import tensorflow as tf\n",
    "from keras.models import Sequential\n",
    "from keras.layers import Dense, Conv2D, MaxPool2D, Flatten, Dropout\n",
    "from keras.preprocessing.image import ImageDataGenerator\n",
    "from keras.applications.vgg16 import VGG16\n",
    "from keras.optimizers import Adam, RMSprop\n",
    "from keras.callbacks import EarlyStopping, ModelCheckpoint\n",
    "import matplotlib.pyplot as plt\n",
    "from sklearn.metrics import confusion_matrix, classification_report,ConfusionMatrixDisplay\n",
    "\n",
    "from sklearn.model_selection import GridSearchCV\n",
    "from scikeras.wrappers import KerasClassifier"
   ]
  },
  {
   "cell_type": "code",
   "execution_count": 2,
   "id": "0d3490ad",
   "metadata": {},
   "outputs": [],
   "source": [
    "ziploc =\"E:/School/UU/PATREC/CXR_project/\"\n",
    "imgloc = \"E:/School/UU\\PATREC/.darwin/datasets/v7-labs/covid-19-chest-x-ray-dataset/images/\"\n",
    "store_loc = \"E:/School/UU/PATREC/.darwin/datasets/v7-labs/augmented_loc/\"\n",
    "\n",
    "# zip file locs\n",
    "train_zf = zipfile.ZipFile(ziploc+'final_train_data.zip') \n",
    "val_zf = zipfile.ZipFile(ziploc+'final_val_data.zip') \n",
    "test_zf = zipfile.ZipFile(ziploc+'test_data.zip') \n",
    "train_df = pd.read_csv(train_zf.open('final_train_data.csv'))\n",
    "val_df = pd.read_csv(val_zf.open('final_val_data.csv'))\n",
    "test_df = pd.read_csv(test_zf.open('val_data.csv'))\n",
    "\n",
    "#augmented image location\n",
    "train_dir = \"E:/School/UU/PATREC/.darwin/datasets/v7-labs/augmented_loc/train\"\n",
    "val_dir = \"E:/School/UU/PATREC/.darwin/datasets/v7-labs/augmented_loc/val\""
   ]
  },
  {
   "cell_type": "code",
   "execution_count": 3,
   "id": "c5c62825",
   "metadata": {},
   "outputs": [],
   "source": [
    "\n",
    "def label(df):\n",
    "    df[\"label\"] = np.nan\n",
    "    df.loc[df[\"type\"] == \"No Pneumonia\", 'label'] = \"A\"\n",
    "    df.loc[df[\"type\"] == \"Bacterial Pneumonia\", 'label'] = \"B\"\n",
    "#     df.loc[df[\"type\"] == \"Fungal Pneumonia\", 'label'] = \"C\"\n",
    "    df.loc[df[\"type\"] == \"Viral Pneumonia\", 'label'] = \"D\"\n",
    "    df.loc[df[\"Covid\"] == True, 'label'] = \"C\"\n",
    "#     df.loc[df[\"type\"] == \"Undefined Pneumonia\", 'label'] = \"F\"\n",
    "    return df"
   ]
  },
  {
   "cell_type": "code",
   "execution_count": 4,
   "id": "4cf6ef21",
   "metadata": {},
   "outputs": [],
   "source": [
    "test = label(test_df)\n",
    "test_df = test[test['label'].notna()]"
   ]
  },
  {
   "cell_type": "markdown",
   "id": "9a003534",
   "metadata": {},
   "source": [
    "## dataloader"
   ]
  },
  {
   "cell_type": "code",
   "execution_count": 5,
   "id": "9710a1eb",
   "metadata": {},
   "outputs": [
    {
     "name": "stdout",
     "output_type": "stream",
     "text": [
      "Found 9984 validated image filenames belonging to 4 classes.\n",
      "Found 1248 validated image filenames belonging to 4 classes.\n",
      "Found 641 validated image filenames.\n"
     ]
    }
   ],
   "source": [
    "# rescale and reproduceabillity \n",
    "seed = 4\n",
    "tf.random.set_seed(seed)\n",
    "datagenerator =  ImageDataGenerator(rescale= 1/255)\n",
    "\n",
    "# Make train rescled\n",
    "train_data = datagenerator.flow_from_dataframe(\n",
    "        dataframe = train_df,\n",
    "        directory = store_loc +\"train\",\n",
    "        x_col = \"ogfilename\",\n",
    "        y_col = \"label\",\n",
    "        class_mode = \"categorical\",\n",
    "        batch_size = 50,\n",
    "        seed = seed,\n",
    "        shuffle = True,\n",
    "        target_size = (224,224), # changed values for vgg16\n",
    "        keep_aspect_ratio = True,\n",
    "        validate_filenames= True)\n",
    "\n",
    "# Make val data\n",
    "val_data = datagenerator.flow_from_dataframe(\n",
    "        dataframe = val_df,\n",
    "        directory = store_loc +\"val\",\n",
    "        x_col = \"ogfilename\",\n",
    "        y_col = \"label\",\n",
    "        class_mode = \"categorical\",\n",
    "        batch_size = 50,\n",
    "        seed = seed,\n",
    "        shuffle = True,\n",
    "        target_size = (224,224), # changed values for vgg16\n",
    "        keep_aspect_ratio = True,\n",
    "        validate_filenames= True)\n",
    "\n",
    "# Make test data\n",
    "test_data = datagenerator.flow_from_dataframe(\n",
    "        dataframe = test_df,\n",
    "        directory = imgloc,\n",
    "        x_col = \"ogfilename\",\n",
    "        y_col = None,\n",
    "        class_mode = None,\n",
    "        batch_size = 1,\n",
    "        seed = seed,\n",
    "        shuffle = False,\n",
    "        target_size = (224,224), # changed values for vgg16\n",
    "        keep_aspect_ratio = True,\n",
    "        validate_filenames= True)"
   ]
  },
  {
   "cell_type": "code",
   "execution_count": 17,
   "id": "a9a5d754",
   "metadata": {},
   "outputs": [
    {
     "data": {
      "text/plain": [
       "<keras.preprocessing.image.DataFrameIterator at 0x2a9db537010>"
      ]
     },
     "execution_count": 17,
     "metadata": {},
     "output_type": "execute_result"
    }
   ],
   "source": [
    "train_data\n"
   ]
  },
  {
   "cell_type": "code",
   "execution_count": 6,
   "id": "333de54c",
   "metadata": {},
   "outputs": [],
   "source": [
    "def get_model(weight=\"imagenet\", include_top_layer= False, input_size =(224,224,3), trainable =False, classes =4, optimizer='sgd'):\n",
    "    vgg =  VGG16(weights=weight, include_top=include_top_layer, input_shape = input_size)\n",
    "    model = Sequential()\n",
    "    model.add(vgg)\n",
    "    model.add(Dropout(0.3))\n",
    "    model.add(Flatten())\n",
    "    model.add(Dropout(0.5))\n",
    "    model.add(Dense(classes, activation='softmax'))\n",
    "    model.layers[0].trainable = trainable\n",
    "    model.compile(loss='categorical_crossentropy', \n",
    "                  optimizer=optimizer, \n",
    "                  metrics=[\"accuracy\"])\n",
    "    return model"
   ]
  },
  {
   "cell_type": "code",
   "execution_count": 7,
   "id": "a28ce896",
   "metadata": {},
   "outputs": [],
   "source": [
    "kears_estimator = KerasClassifier(build_fn=get_model, verbose=0)"
   ]
  },
  {
   "cell_type": "code",
   "execution_count": 9,
   "id": "c1ae3503",
   "metadata": {},
   "outputs": [],
   "source": [
    "optimizers = ['rmsprop', 'adam']\n",
    "\n",
    "param_grid = dict(optimizer=optimizers)"
   ]
  },
  {
   "cell_type": "code",
   "execution_count": 12,
   "id": "d4217728",
   "metadata": {},
   "outputs": [],
   "source": [
    "grid = GridSearchCV(estimator=kears_estimator, param_grid=param_grid, cv =3, return_train_score= True, n_jobs=1)"
   ]
  },
  {
   "cell_type": "code",
   "execution_count": 19,
   "id": "382cced5",
   "metadata": {},
   "outputs": [
    {
     "ename": "ValueError",
     "evalue": "\nAll the 6 fits failed.\nIt is very likely that your model is misconfigured.\nYou can try to debug the error by setting error_score='raise'.\n\nBelow are more details about the failures:\n--------------------------------------------------------------------------------\n4 fits failed with the following error:\nTraceback (most recent call last):\n  File \"C:\\Users\\jensr\\AppData\\Local\\Programs\\Python\\Python310\\lib\\site-packages\\sklearn\\model_selection\\_validation.py\", line 686, in _fit_and_score\n    estimator.fit(X_train, y_train, **fit_params)\n  File \"C:\\Users\\jensr\\AppData\\Local\\Programs\\Python\\Python310\\lib\\site-packages\\scikeras\\wrappers.py\", line 1494, in fit\n    super().fit(X=X, y=y, sample_weight=sample_weight, **kwargs)\n  File \"C:\\Users\\jensr\\AppData\\Local\\Programs\\Python\\Python310\\lib\\site-packages\\scikeras\\wrappers.py\", line 762, in fit\n    self._fit(\n  File \"C:\\Users\\jensr\\AppData\\Local\\Programs\\Python\\Python310\\lib\\site-packages\\scikeras\\wrappers.py\", line 918, in _fit\n    X, y = self._initialize(X, y)\n  File \"C:\\Users\\jensr\\AppData\\Local\\Programs\\Python\\Python310\\lib\\site-packages\\scikeras\\wrappers.py\", line 846, in _initialize\n    X, y = self._validate_data(X, y, reset=True)\n  File \"C:\\Users\\jensr\\AppData\\Local\\Programs\\Python\\Python310\\lib\\site-packages\\scikeras\\wrappers.py\", line 618, in _validate_data\n    X, y = check_X_y(\n  File \"C:\\Users\\jensr\\AppData\\Local\\Programs\\Python\\Python310\\lib\\site-packages\\sklearn\\utils\\validation.py\", line 1074, in check_X_y\n    X = check_array(\n  File \"C:\\Users\\jensr\\AppData\\Local\\Programs\\Python\\Python310\\lib\\site-packages\\sklearn\\utils\\validation.py\", line 856, in check_array\n    array = np.asarray(array, order=order, dtype=dtype)\nValueError: setting an array element with a sequence. The requested array has an inhomogeneous shape after 2 dimensions. The detected shape was (133, 2) + inhomogeneous part.\n\n--------------------------------------------------------------------------------\n2 fits failed with the following error:\nTraceback (most recent call last):\n  File \"C:\\Users\\jensr\\AppData\\Local\\Programs\\Python\\Python310\\lib\\site-packages\\sklearn\\model_selection\\_validation.py\", line 686, in _fit_and_score\n    estimator.fit(X_train, y_train, **fit_params)\n  File \"C:\\Users\\jensr\\AppData\\Local\\Programs\\Python\\Python310\\lib\\site-packages\\scikeras\\wrappers.py\", line 1494, in fit\n    super().fit(X=X, y=y, sample_weight=sample_weight, **kwargs)\n  File \"C:\\Users\\jensr\\AppData\\Local\\Programs\\Python\\Python310\\lib\\site-packages\\scikeras\\wrappers.py\", line 762, in fit\n    self._fit(\n  File \"C:\\Users\\jensr\\AppData\\Local\\Programs\\Python\\Python310\\lib\\site-packages\\scikeras\\wrappers.py\", line 918, in _fit\n    X, y = self._initialize(X, y)\n  File \"C:\\Users\\jensr\\AppData\\Local\\Programs\\Python\\Python310\\lib\\site-packages\\scikeras\\wrappers.py\", line 846, in _initialize\n    X, y = self._validate_data(X, y, reset=True)\n  File \"C:\\Users\\jensr\\AppData\\Local\\Programs\\Python\\Python310\\lib\\site-packages\\scikeras\\wrappers.py\", line 618, in _validate_data\n    X, y = check_X_y(\n  File \"C:\\Users\\jensr\\AppData\\Local\\Programs\\Python\\Python310\\lib\\site-packages\\sklearn\\utils\\validation.py\", line 1074, in check_X_y\n    X = check_array(\n  File \"C:\\Users\\jensr\\AppData\\Local\\Programs\\Python\\Python310\\lib\\site-packages\\sklearn\\utils\\validation.py\", line 856, in check_array\n    array = np.asarray(array, order=order, dtype=dtype)\nValueError: setting an array element with a sequence. The requested array has an inhomogeneous shape after 3 dimensions. The detected shape was (134, 2, 50) + inhomogeneous part.\n",
     "output_type": "error",
     "traceback": [
      "\u001B[1;31m---------------------------------------------------------------------------\u001B[0m",
      "\u001B[1;31mValueError\u001B[0m                                Traceback (most recent call last)",
      "Cell \u001B[1;32mIn [19], line 1\u001B[0m\n\u001B[1;32m----> 1\u001B[0m grid_result \u001B[38;5;241m=\u001B[39m \u001B[43mgrid\u001B[49m\u001B[38;5;241;43m.\u001B[39;49m\u001B[43mfit\u001B[49m\u001B[43m(\u001B[49m\u001B[43mtrain_data\u001B[49m\u001B[43m,\u001B[49m\u001B[43m \u001B[49m\u001B[43mtrain_df\u001B[49m\u001B[38;5;241;43m.\u001B[39;49m\u001B[43mlabel\u001B[49m\u001B[43m[\u001B[49m\u001B[43m:\u001B[49m\u001B[38;5;241;43m200\u001B[39;49m\u001B[43m]\u001B[49m\u001B[43m)\u001B[49m\n",
      "File \u001B[1;32m~\\AppData\\Local\\Programs\\Python\\Python310\\lib\\site-packages\\sklearn\\model_selection\\_search.py:875\u001B[0m, in \u001B[0;36mBaseSearchCV.fit\u001B[1;34m(self, X, y, groups, **fit_params)\u001B[0m\n\u001B[0;32m    869\u001B[0m     results \u001B[38;5;241m=\u001B[39m \u001B[38;5;28mself\u001B[39m\u001B[38;5;241m.\u001B[39m_format_results(\n\u001B[0;32m    870\u001B[0m         all_candidate_params, n_splits, all_out, all_more_results\n\u001B[0;32m    871\u001B[0m     )\n\u001B[0;32m    873\u001B[0m     \u001B[38;5;28;01mreturn\u001B[39;00m results\n\u001B[1;32m--> 875\u001B[0m \u001B[38;5;28;43mself\u001B[39;49m\u001B[38;5;241;43m.\u001B[39;49m\u001B[43m_run_search\u001B[49m\u001B[43m(\u001B[49m\u001B[43mevaluate_candidates\u001B[49m\u001B[43m)\u001B[49m\n\u001B[0;32m    877\u001B[0m \u001B[38;5;66;03m# multimetric is determined here because in the case of a callable\u001B[39;00m\n\u001B[0;32m    878\u001B[0m \u001B[38;5;66;03m# self.scoring the return type is only known after calling\u001B[39;00m\n\u001B[0;32m    879\u001B[0m first_test_score \u001B[38;5;241m=\u001B[39m all_out[\u001B[38;5;241m0\u001B[39m][\u001B[38;5;124m\"\u001B[39m\u001B[38;5;124mtest_scores\u001B[39m\u001B[38;5;124m\"\u001B[39m]\n",
      "File \u001B[1;32m~\\AppData\\Local\\Programs\\Python\\Python310\\lib\\site-packages\\sklearn\\model_selection\\_search.py:1379\u001B[0m, in \u001B[0;36mGridSearchCV._run_search\u001B[1;34m(self, evaluate_candidates)\u001B[0m\n\u001B[0;32m   1377\u001B[0m \u001B[38;5;28;01mdef\u001B[39;00m \u001B[38;5;21m_run_search\u001B[39m(\u001B[38;5;28mself\u001B[39m, evaluate_candidates):\n\u001B[0;32m   1378\u001B[0m     \u001B[38;5;124;03m\"\"\"Search all candidates in param_grid\"\"\"\u001B[39;00m\n\u001B[1;32m-> 1379\u001B[0m     \u001B[43mevaluate_candidates\u001B[49m\u001B[43m(\u001B[49m\u001B[43mParameterGrid\u001B[49m\u001B[43m(\u001B[49m\u001B[38;5;28;43mself\u001B[39;49m\u001B[38;5;241;43m.\u001B[39;49m\u001B[43mparam_grid\u001B[49m\u001B[43m)\u001B[49m\u001B[43m)\u001B[49m\n",
      "File \u001B[1;32m~\\AppData\\Local\\Programs\\Python\\Python310\\lib\\site-packages\\sklearn\\model_selection\\_search.py:852\u001B[0m, in \u001B[0;36mBaseSearchCV.fit.<locals>.evaluate_candidates\u001B[1;34m(candidate_params, cv, more_results)\u001B[0m\n\u001B[0;32m    845\u001B[0m \u001B[38;5;28;01melif\u001B[39;00m \u001B[38;5;28mlen\u001B[39m(out) \u001B[38;5;241m!=\u001B[39m n_candidates \u001B[38;5;241m*\u001B[39m n_splits:\n\u001B[0;32m    846\u001B[0m     \u001B[38;5;28;01mraise\u001B[39;00m \u001B[38;5;167;01mValueError\u001B[39;00m(\n\u001B[0;32m    847\u001B[0m         \u001B[38;5;124m\"\u001B[39m\u001B[38;5;124mcv.split and cv.get_n_splits returned \u001B[39m\u001B[38;5;124m\"\u001B[39m\n\u001B[0;32m    848\u001B[0m         \u001B[38;5;124m\"\u001B[39m\u001B[38;5;124minconsistent results. Expected \u001B[39m\u001B[38;5;132;01m{}\u001B[39;00m\u001B[38;5;124m \u001B[39m\u001B[38;5;124m\"\u001B[39m\n\u001B[0;32m    849\u001B[0m         \u001B[38;5;124m\"\u001B[39m\u001B[38;5;124msplits, got \u001B[39m\u001B[38;5;132;01m{}\u001B[39;00m\u001B[38;5;124m\"\u001B[39m\u001B[38;5;241m.\u001B[39mformat(n_splits, \u001B[38;5;28mlen\u001B[39m(out) \u001B[38;5;241m/\u001B[39m\u001B[38;5;241m/\u001B[39m n_candidates)\n\u001B[0;32m    850\u001B[0m     )\n\u001B[1;32m--> 852\u001B[0m \u001B[43m_warn_or_raise_about_fit_failures\u001B[49m\u001B[43m(\u001B[49m\u001B[43mout\u001B[49m\u001B[43m,\u001B[49m\u001B[43m \u001B[49m\u001B[38;5;28;43mself\u001B[39;49m\u001B[38;5;241;43m.\u001B[39;49m\u001B[43merror_score\u001B[49m\u001B[43m)\u001B[49m\n\u001B[0;32m    854\u001B[0m \u001B[38;5;66;03m# For callable self.scoring, the return type is only know after\u001B[39;00m\n\u001B[0;32m    855\u001B[0m \u001B[38;5;66;03m# calling. If the return type is a dictionary, the error scores\u001B[39;00m\n\u001B[0;32m    856\u001B[0m \u001B[38;5;66;03m# can now be inserted with the correct key. The type checking\u001B[39;00m\n\u001B[0;32m    857\u001B[0m \u001B[38;5;66;03m# of out will be done in `_insert_error_scores`.\u001B[39;00m\n\u001B[0;32m    858\u001B[0m \u001B[38;5;28;01mif\u001B[39;00m callable(\u001B[38;5;28mself\u001B[39m\u001B[38;5;241m.\u001B[39mscoring):\n",
      "File \u001B[1;32m~\\AppData\\Local\\Programs\\Python\\Python310\\lib\\site-packages\\sklearn\\model_selection\\_validation.py:367\u001B[0m, in \u001B[0;36m_warn_or_raise_about_fit_failures\u001B[1;34m(results, error_score)\u001B[0m\n\u001B[0;32m    360\u001B[0m \u001B[38;5;28;01mif\u001B[39;00m num_failed_fits \u001B[38;5;241m==\u001B[39m num_fits:\n\u001B[0;32m    361\u001B[0m     all_fits_failed_message \u001B[38;5;241m=\u001B[39m (\n\u001B[0;32m    362\u001B[0m         \u001B[38;5;124mf\u001B[39m\u001B[38;5;124m\"\u001B[39m\u001B[38;5;130;01m\\n\u001B[39;00m\u001B[38;5;124mAll the \u001B[39m\u001B[38;5;132;01m{\u001B[39;00mnum_fits\u001B[38;5;132;01m}\u001B[39;00m\u001B[38;5;124m fits failed.\u001B[39m\u001B[38;5;130;01m\\n\u001B[39;00m\u001B[38;5;124m\"\u001B[39m\n\u001B[0;32m    363\u001B[0m         \u001B[38;5;124m\"\u001B[39m\u001B[38;5;124mIt is very likely that your model is misconfigured.\u001B[39m\u001B[38;5;130;01m\\n\u001B[39;00m\u001B[38;5;124m\"\u001B[39m\n\u001B[0;32m    364\u001B[0m         \u001B[38;5;124m\"\u001B[39m\u001B[38;5;124mYou can try to debug the error by setting error_score=\u001B[39m\u001B[38;5;124m'\u001B[39m\u001B[38;5;124mraise\u001B[39m\u001B[38;5;124m'\u001B[39m\u001B[38;5;124m.\u001B[39m\u001B[38;5;130;01m\\n\u001B[39;00m\u001B[38;5;130;01m\\n\u001B[39;00m\u001B[38;5;124m\"\u001B[39m\n\u001B[0;32m    365\u001B[0m         \u001B[38;5;124mf\u001B[39m\u001B[38;5;124m\"\u001B[39m\u001B[38;5;124mBelow are more details about the failures:\u001B[39m\u001B[38;5;130;01m\\n\u001B[39;00m\u001B[38;5;132;01m{\u001B[39;00mfit_errors_summary\u001B[38;5;132;01m}\u001B[39;00m\u001B[38;5;124m\"\u001B[39m\n\u001B[0;32m    366\u001B[0m     )\n\u001B[1;32m--> 367\u001B[0m     \u001B[38;5;28;01mraise\u001B[39;00m \u001B[38;5;167;01mValueError\u001B[39;00m(all_fits_failed_message)\n\u001B[0;32m    369\u001B[0m \u001B[38;5;28;01melse\u001B[39;00m:\n\u001B[0;32m    370\u001B[0m     some_fits_failed_message \u001B[38;5;241m=\u001B[39m (\n\u001B[0;32m    371\u001B[0m         \u001B[38;5;124mf\u001B[39m\u001B[38;5;124m\"\u001B[39m\u001B[38;5;130;01m\\n\u001B[39;00m\u001B[38;5;132;01m{\u001B[39;00mnum_failed_fits\u001B[38;5;132;01m}\u001B[39;00m\u001B[38;5;124m fits failed out of a total of \u001B[39m\u001B[38;5;132;01m{\u001B[39;00mnum_fits\u001B[38;5;132;01m}\u001B[39;00m\u001B[38;5;124m.\u001B[39m\u001B[38;5;130;01m\\n\u001B[39;00m\u001B[38;5;124m\"\u001B[39m\n\u001B[0;32m    372\u001B[0m         \u001B[38;5;124m\"\u001B[39m\u001B[38;5;124mThe score on these train-test partitions for these parameters\u001B[39m\u001B[38;5;124m\"\u001B[39m\n\u001B[1;32m   (...)\u001B[0m\n\u001B[0;32m    376\u001B[0m         \u001B[38;5;124mf\u001B[39m\u001B[38;5;124m\"\u001B[39m\u001B[38;5;124mBelow are more details about the failures:\u001B[39m\u001B[38;5;130;01m\\n\u001B[39;00m\u001B[38;5;132;01m{\u001B[39;00mfit_errors_summary\u001B[38;5;132;01m}\u001B[39;00m\u001B[38;5;124m\"\u001B[39m\n\u001B[0;32m    377\u001B[0m     )\n",
      "\u001B[1;31mValueError\u001B[0m: \nAll the 6 fits failed.\nIt is very likely that your model is misconfigured.\nYou can try to debug the error by setting error_score='raise'.\n\nBelow are more details about the failures:\n--------------------------------------------------------------------------------\n4 fits failed with the following error:\nTraceback (most recent call last):\n  File \"C:\\Users\\jensr\\AppData\\Local\\Programs\\Python\\Python310\\lib\\site-packages\\sklearn\\model_selection\\_validation.py\", line 686, in _fit_and_score\n    estimator.fit(X_train, y_train, **fit_params)\n  File \"C:\\Users\\jensr\\AppData\\Local\\Programs\\Python\\Python310\\lib\\site-packages\\scikeras\\wrappers.py\", line 1494, in fit\n    super().fit(X=X, y=y, sample_weight=sample_weight, **kwargs)\n  File \"C:\\Users\\jensr\\AppData\\Local\\Programs\\Python\\Python310\\lib\\site-packages\\scikeras\\wrappers.py\", line 762, in fit\n    self._fit(\n  File \"C:\\Users\\jensr\\AppData\\Local\\Programs\\Python\\Python310\\lib\\site-packages\\scikeras\\wrappers.py\", line 918, in _fit\n    X, y = self._initialize(X, y)\n  File \"C:\\Users\\jensr\\AppData\\Local\\Programs\\Python\\Python310\\lib\\site-packages\\scikeras\\wrappers.py\", line 846, in _initialize\n    X, y = self._validate_data(X, y, reset=True)\n  File \"C:\\Users\\jensr\\AppData\\Local\\Programs\\Python\\Python310\\lib\\site-packages\\scikeras\\wrappers.py\", line 618, in _validate_data\n    X, y = check_X_y(\n  File \"C:\\Users\\jensr\\AppData\\Local\\Programs\\Python\\Python310\\lib\\site-packages\\sklearn\\utils\\validation.py\", line 1074, in check_X_y\n    X = check_array(\n  File \"C:\\Users\\jensr\\AppData\\Local\\Programs\\Python\\Python310\\lib\\site-packages\\sklearn\\utils\\validation.py\", line 856, in check_array\n    array = np.asarray(array, order=order, dtype=dtype)\nValueError: setting an array element with a sequence. The requested array has an inhomogeneous shape after 2 dimensions. The detected shape was (133, 2) + inhomogeneous part.\n\n--------------------------------------------------------------------------------\n2 fits failed with the following error:\nTraceback (most recent call last):\n  File \"C:\\Users\\jensr\\AppData\\Local\\Programs\\Python\\Python310\\lib\\site-packages\\sklearn\\model_selection\\_validation.py\", line 686, in _fit_and_score\n    estimator.fit(X_train, y_train, **fit_params)\n  File \"C:\\Users\\jensr\\AppData\\Local\\Programs\\Python\\Python310\\lib\\site-packages\\scikeras\\wrappers.py\", line 1494, in fit\n    super().fit(X=X, y=y, sample_weight=sample_weight, **kwargs)\n  File \"C:\\Users\\jensr\\AppData\\Local\\Programs\\Python\\Python310\\lib\\site-packages\\scikeras\\wrappers.py\", line 762, in fit\n    self._fit(\n  File \"C:\\Users\\jensr\\AppData\\Local\\Programs\\Python\\Python310\\lib\\site-packages\\scikeras\\wrappers.py\", line 918, in _fit\n    X, y = self._initialize(X, y)\n  File \"C:\\Users\\jensr\\AppData\\Local\\Programs\\Python\\Python310\\lib\\site-packages\\scikeras\\wrappers.py\", line 846, in _initialize\n    X, y = self._validate_data(X, y, reset=True)\n  File \"C:\\Users\\jensr\\AppData\\Local\\Programs\\Python\\Python310\\lib\\site-packages\\scikeras\\wrappers.py\", line 618, in _validate_data\n    X, y = check_X_y(\n  File \"C:\\Users\\jensr\\AppData\\Local\\Programs\\Python\\Python310\\lib\\site-packages\\sklearn\\utils\\validation.py\", line 1074, in check_X_y\n    X = check_array(\n  File \"C:\\Users\\jensr\\AppData\\Local\\Programs\\Python\\Python310\\lib\\site-packages\\sklearn\\utils\\validation.py\", line 856, in check_array\n    array = np.asarray(array, order=order, dtype=dtype)\nValueError: setting an array element with a sequence. The requested array has an inhomogeneous shape after 3 dimensions. The detected shape was (134, 2, 50) + inhomogeneous part.\n"
     ]
    }
   ],
   "source": [
    "grid_result = grid.fit(train_data, train_df.label[:200])"
   ]
  }
 ],
 "metadata": {
  "kernelspec": {
   "display_name": "Python 3 (ipykernel)",
   "language": "python",
   "name": "python3"
  },
  "language_info": {
   "codemirror_mode": {
    "name": "ipython",
    "version": 3
   },
   "file_extension": ".py",
   "mimetype": "text/x-python",
   "name": "python",
   "nbconvert_exporter": "python",
   "pygments_lexer": "ipython3",
   "version": "3.10.7"
  }
 },
 "nbformat": 4,
 "nbformat_minor": 5
}
